import { render, screen } from '@testing-library/react'
import { describe, it, expect, vi, beforeEach, afterEach } from 'vitest'
import userEvent from '@testing-library/user-event'
import { ErrorBoundary } from '@/components/ui/ErrorBoundary'

// Component that throws an error for testing
function ThrowError({ shouldThrow }: { shouldThrow: boolean }) {
  if (shouldThrow) {
    throw new Error('Test error')
  }
  return <div>No error</div>
}

describe('ErrorBoundary Component', () => {
  // Suppress console.error for these tests
  const originalError = console.error
  beforeEach(() => {
    console.error = vi.fn()
  })
  
  afterEach(() => {
    console.error = originalError
  })

  it('renders children when there is no error', () => {
    render(
      <ErrorBoundary>
        <ThrowError shouldThrow={false} />
      </ErrorBoundary>
    )
    
    expect(screen.getByText('No error')).toBeInTheDocument()
  })

  it('renders error boundary UI when there is an error', () => {
    render(
      <ErrorBoundary>
        <ThrowError shouldThrow={true} />
      </ErrorBoundary>
    )
    
    expect(screen.getByText(/Something went wrong/)).toBeInTheDocument()
    expect(screen.getByRole('button', { name: /try again/i })).toBeInTheDocument()
  })

  it('renders custom fallback when provided', () => {
    const customFallback = <div>Custom error message</div>
    
    render(
      <ErrorBoundary fallback={customFallback}>
        <ThrowError shouldThrow={true} />
      </ErrorBoundary>
    )
    
    expect(screen.getByText('Custom error message')).toBeInTheDocument()
  })

  it('calls onError callback when error occurs', () => {
    const onError = vi.fn()
    
    render(
      <ErrorBoundary onError={onError}>
        <ThrowError shouldThrow={true} />
      </ErrorBoundary>
    )
    
    expect(onError).toHaveBeenCalledWith(
      expect.any(Error),
      expect.objectContaining({
        componentStack: expect.any(String)
      })
    )
  })

  it('renders try again button that can be clicked', async () => {
    const user = userEvent.setup()
    
    render(
      <ErrorBoundary>
        <ThrowError shouldThrow={true} />
      </ErrorBoundary>
    )
    
    // Error boundary should be showing with try again button
    expect(screen.getByText(/Something went wrong/)).toBeInTheDocument()
    const tryAgainButton = screen.getByRole('button', { name: /try again/i })
    expect(tryAgainButton).toBeInTheDocument()
    
    // Button should be clickable (no error thrown)
    await user.click(tryAgainButton)
    
    // Button should still be present after click (error state persists)
    expect(screen.getByRole('button', { name: /try again/i })).toBeInTheDocument()
  })
})